ERROR    asyncio:base_events.py:1821 Exception in callback SyncBase._sync.<locals>.<lambda>(<Task finishe...> result=None>) at /usr/local/lib/python3.12/dist-packages/playwright/_impl/_sync_base.py:111
handle: <Handle SyncBase._sync.<locals>.<lambda>(<Task finishe...> result=None>) at /usr/local/lib/python3.12/dist-packages/playwright/_impl/_sync_base.py:111>
Traceback (most recent call last):
  File "/usr/lib/python3.12/asyncio/events.py", line 88, in _run
    self._context.run(self._callback, *self._args)
  File "/usr/local/lib/python3.12/dist-packages/playwright/_impl/_sync_base.py", line 111, in <lambda>
    task.add_done_callback(lambda _: g_self.switch())
                                     ^^^^^^^^^^^^^^^
  File "/usr/local/lib/python3.12/dist-packages/playwright/_impl/_connection.py", line 471, in _listener_with_error_handler_attached
    potential_future = listener(params)
                       ^^^^^^^^^^^^^^^^
  File "/usr/local/lib/python3.12/dist-packages/playwright/_impl/_browser_context.py", line 167, in <lambda>
    "dialog", lambda params: self._on_dialog(from_channel(params["dialog"]))
                             ^^^^^^^^^^^^^^^^^^^^^^^^^^^^^^^^^^^^^^^^^^^^^^^
  File "/usr/local/lib/python3.12/dist-packages/playwright/_impl/_browser_context.py", line 708, in _on_dialog
    has_listeners = page.emit(Page.Events.Dialog, dialog) or has_listeners
                    ^^^^^^^^^^^^^^^^^^^^^^^^^^^^^^^^^^^^^
  File "/usr/local/lib/python3.12/dist-packages/pyee/asyncio.py", line 70, in emit
    return super().emit(event, *args, **kwargs)
           ^^^^^^^^^^^^^^^^^^^^^^^^^^^^^^^^^^^^
  File "/usr/local/lib/python3.12/dist-packages/pyee/base.py", line 220, in emit
    handled = self._call_handlers(event, args, kwargs)
              ^^^^^^^^^^^^^^^^^^^^^^^^^^^^^^^^^^^^^^^^
  File "/usr/local/lib/python3.12/dist-packages/pyee/base.py", line 196, in _call_handlers
    self._emit_run(f, args, kwargs)
  File "/usr/local/lib/python3.12/dist-packages/pyee/asyncio.py", line 81, in _emit_run
    self.emit("error", exc)
  File "/usr/local/lib/python3.12/dist-packages/pyee/asyncio.py", line 70, in emit
    return super().emit(event, *args, **kwargs)
           ^^^^^^^^^^^^^^^^^^^^^^^^^^^^^^^^^^^^
  File "/usr/local/lib/python3.12/dist-packages/pyee/base.py", line 223, in emit
    self._emit_handle_potential_error(event, args[0] if args else None)
  File "/usr/local/lib/python3.12/dist-packages/pyee/base.py", line 181, in _emit_handle_potential_error
    raise error
  File "/usr/local/lib/python3.12/dist-packages/pyee/asyncio.py", line 79, in _emit_run
    coro: Any = f(*args, **kwargs)
                ^^^^^^^^^^^^^^^^^^
  File "/usr/local/lib/python3.12/dist-packages/pyee/base.py", line 250, in g
    return f(*args, **kwargs)
           ^^^^^^^^^^^^^^^^^^
  File "/usr/local/lib/python3.12/dist-packages/playwright/_impl/_impl_to_api_mapping.py", line 123, in wrapper_func
    return handler(
           ^^^^^^^^
  File "/app/tests/pages/alert_page.py", line 38, in handle_second_dialog
    assert dialog.message == "Yes"
           ^^^^^^^^^^^^^^^^^^^^^^^
AssertionError
ERROR    asyncio:base_events.py:1821 Exception in callback SyncBase._sync.<locals>.<lambda>(<Task finishe...> result=None>) at /usr/local/lib/python3.12/dist-packages/playwright/_impl/_sync_base.py:111
handle: <Handle SyncBase._sync.<locals>.<lambda>(<Task finishe...> result=None>) at /usr/local/lib/python3.12/dist-packages/playwright/_impl/_sync_base.py:111>
Traceback (most recent call last):
  File "/usr/lib/python3.12/asyncio/events.py", line 88, in _run
    self._context.run(self._callback, *self._args)
  File "/usr/local/lib/python3.12/dist-packages/playwright/_impl/_sync_base.py", line 111, in <lambda>
    task.add_done_callback(lambda _: g_self.switch())
                                     ^^^^^^^^^^^^^^^
  File "/usr/local/lib/python3.12/dist-packages/playwright/_impl/_connection.py", line 471, in _listener_with_error_handler_attached
    potential_future = listener(params)
                       ^^^^^^^^^^^^^^^^
  File "/usr/local/lib/python3.12/dist-packages/playwright/_impl/_browser_context.py", line 167, in <lambda>
    "dialog", lambda params: self._on_dialog(from_channel(params["dialog"]))
                             ^^^^^^^^^^^^^^^^^^^^^^^^^^^^^^^^^^^^^^^^^^^^^^^
  File "/usr/local/lib/python3.12/dist-packages/playwright/_impl/_browser_context.py", line 708, in _on_dialog
    has_listeners = page.emit(Page.Events.Dialog, dialog) or has_listeners
                    ^^^^^^^^^^^^^^^^^^^^^^^^^^^^^^^^^^^^^
  File "/usr/local/lib/python3.12/dist-packages/pyee/asyncio.py", line 70, in emit
    return super().emit(event, *args, **kwargs)
           ^^^^^^^^^^^^^^^^^^^^^^^^^^^^^^^^^^^^
  File "/usr/local/lib/python3.12/dist-packages/pyee/base.py", line 220, in emit
    handled = self._call_handlers(event, args, kwargs)
              ^^^^^^^^^^^^^^^^^^^^^^^^^^^^^^^^^^^^^^^^
  File "/usr/local/lib/python3.12/dist-packages/pyee/base.py", line 196, in _call_handlers
    self._emit_run(f, args, kwargs)
  File "/usr/local/lib/python3.12/dist-packages/pyee/asyncio.py", line 81, in _emit_run
    self.emit("error", exc)
  File "/usr/local/lib/python3.12/dist-packages/pyee/asyncio.py", line 70, in emit
    return super().emit(event, *args, **kwargs)
           ^^^^^^^^^^^^^^^^^^^^^^^^^^^^^^^^^^^^
  File "/usr/local/lib/python3.12/dist-packages/pyee/base.py", line 223, in emit
    self._emit_handle_potential_error(event, args[0] if args else None)
  File "/usr/local/lib/python3.12/dist-packages/pyee/base.py", line 181, in _emit_handle_potential_error
    raise error
  File "/usr/local/lib/python3.12/dist-packages/pyee/asyncio.py", line 79, in _emit_run
    coro: Any = f(*args, **kwargs)
                ^^^^^^^^^^^^^^^^^^
  File "/usr/local/lib/python3.12/dist-packages/pyee/base.py", line 250, in g
    return f(*args, **kwargs)
           ^^^^^^^^^^^^^^^^^^
  File "/usr/local/lib/python3.12/dist-packages/playwright/_impl/_impl_to_api_mapping.py", line 123, in wrapper_func
    return handler(
           ^^^^^^^^
  File "/app/tests/pages/alert_page.py", line 54, in handle_result_dialog
    assert dialog.message == "dogs"
           ^^^^^^^^^^^^^^^^^^^^^^^^
AssertionError